<?xml version="1.0"?>
<robot xmlns:xacro="http://www.ros.org/wiki/xacro" name="omnibot">

  <!-- Base link -->
  <link name="base_link">
    <visual>
      <geometry>
        <box size="0.3 0.3 0.1"/>
      </geometry>
      <material name="blue">
        <color rgba="0.1 0.1 0.8 1"/>
      </material>
    </visual>
    <collision>
      <geometry>
        <box size="0.3 0.3 0.1"/>
      </geometry>
    </collision>
    <inertial>
      <mass value="5.0"/>
      <inertia ixx="0.1" iyy="0.1" izz="0.1" ixy="0" ixz="0" iyz="0"/>
    </inertial>
  </link>

  <!-- 4 Mecanum wheels (simplified as cylinders) -->
  <xacro:macro name="wheel" params="name x y">
    <link name="${name}">
      <visual>
        <geometry>
          <cylinder radius="0.04" length="0.02"/>
        </geometry>
        <material name="black">
          <color rgba="0.02 0.02 0.02 1"/>
        </material>
      </visual>
      <collision>
        <geometry>
          <cylinder radius="0.04" length="0.02"/>
        </geometry>
      </collision>
      <inertial>
        <mass value="0.2"/>
        <inertia ixx="0.001" iyy="0.001" izz="0.001" ixy="0" ixz="0" iyz="0"/>
      </inertial>
    </link>

    <joint name="${name}_joint" type="continuous">
      <parent link="base_link"/>
      <child link="${name}"/>
      <origin xyz="${x} ${y} -0.05" rpy="0 1.5708 0"/>
      <axis xyz="0 1 0"/>
    </joint>
  </xacro:macro>

  <xacro:wheel name="wheel_fl" x="0.12" y="0.12"/>
  <xacro:wheel name="wheel_fr" x="0.12" y="-0.12"/>
  <xacro:wheel name="wheel_rl" x="-0.12" y="0.12"/>
  <xacro:wheel name="wheel_rr" x="-0.12" y="-0.12"/>

</robot>
